Workbook
Name fundos_xp: OFFSET('Fundos XP Locais'!$C$5,0,0,COUNTA('Fundos XP Locais'!$C:$C)-2,1)

Sheet Menu
B2: Menu
D5: Tabela contendo características gerais de todos os fundos da plataforma XP local.
D8: Fundos Internacionais distribuidos em nossa conta global, plataforma Digital.
D11: Fundos da nossa franquia alternativos, incluindo Venture Capital, Private Equity, Private Debt, Trend DI, Real Assets e Private Debt.
D14: Fundos da nossa franquia cetipados, incluindo Imobiliário, Agronegócio, Infraestrutura, Hedge Fund, Special Situations e Private Debt.
D17: Fundos da nossa franquia PR+, incluindo Venture Capital, Private Equity, Private Debt, Trend DI, Real Assets e Private Debt.
D20: Aque é possível encontrar uma descrição de o que seria cada coluna das abas "Fundos Alternativos", "Fundos Cetipados" e "Fundos PR+".
D23: Comentários do gestor sobre atribuição de performance e cenário, além do posicionamento do fundo.
D26: Comparador de caracacterísticas gerais e performance dos diferentes fundos da plataforma
D29: Simulador da receita de taxa de administração e taxa de performance, com a distribuição de diferentes fundos da plataforma
D31: Tabela contendo características gerais dos fundos da indústria
D34: Descrição explicativa de o que seria cada classificação XP feita para os fundos.

Sheet Fundos XP Locais
B1: 1 | C1: 2 | D1: 3 | E1: 4 | F1: 5 | G1: 6 | H1: 7 | I1: 8 | J1: 9 | K1: 10 | L1: 11 | M1: 12 | N1: 13 | O1: 14 | P1: 15 | Q1: 16 | R1: 17 | S1: 18 | T1: 19 | U1: 20 | V1: 21 | W1: 22 | X1: 23 | Y1: 24 | Z1: 25 | AA1: 26 | AB1: 27 | AC1: 28 | AD1: 29 | AE1: 30 | AF1: 31 | AG1: 32 | AH1: 33 | AI1: 34 | AJ1: 35 | AK1: 36 | AL1: 37 | AM1: 38 | AN1: 39 | AO1: 40 | AP1: 41 | AQ1: 42 | AR1: 43 | AS1: 44 | AT1: 45 | AU1: 46 | AV1: 47 | AW1: 48 | AX1: 49 | AY1: 50 | AZ1: 51 | BA1: 52 | BB1: 53 | BC1: 54 | BD1: 55 | BE1: 56 | BF1: 57 | BG1: 58 | BH1: 59 | BI1: 60 | BJ1: 61 | BK1: 62 | BL1: 63 | BM1: 64 | BN1: 65 | BO1: 66 | BP1: 67 | BQ1: 68 | BR1: 69 | BS1: 70 | BT1: 71 | BU1: 72 | BV1: 73 | BW1: 74 | BX1: 75 | BY1: 76 | BZ1: 77 | CA1: 78 | CB1: 79 | CC1: 80 | CD1: 81 | CE1: 82 | CF1: 83 | CG1: 84 | CH1: 85 | CI1: 86 | CJ1: 87 | CK1: 88 | CL1: 89 | CM1: 90 | CN1: 91 | CO1: 92 | CP1: 93 | CQ1: 94 | CR1: 95 | CS1: 96 | CT1: 97 | CU1: 98 | CV1: 99 | CW1: 100 | CX1: 101
B2: XP GUIA DE FUNDOS - Data base 30/04/2026
M3: Classificação | W3: Aplicação | X3: Resgate | AD3: Taxa de Administração | AM3: Rentabilidade Absoluta | AX3: Rentabilidade % CDI | BI3: Rentabilidade CDI +/- | BT3: Indicadores Técnicos | CH3: % Comissão Escritórios** | CJ3: "Margem"
B4: CNPJ | C4: Fundo | D4: Risco XP | E4: Top Fundos | F4: Classificação Morningstar | G4: Gestor | H4: Administrador | I4: Custodiante | J4: Auditor | K4: Disponibilidade | L4: Público | M4: CVM | N4: Anbima | O4: Classificação XP | P4: Tributação | Q4: Aplicação Inicial | R4: Status | S4: Envio de Cota Horário Médio | T4: Movimentação mínima | U4: Saldo de Permanencia | V4: Tipo de Cota | W4: Cotização | X4: Cotização | Y4: Liquidação | Z4: Liquidez total (Cotização + Liquidação) em número (aproximação para filtros) | AA4: Resgate Antecipado | AB4: Taxa de Saída Antecipada | AC4: Fundo Master | AD4: Taxa de Administração | AE4: Taxa de Administração da estrutura (Master + Feeder) | AF4: Taxa de Administração Máxima | AG4: Taxa de Performance (% sobre o que exceder o indexador) | AH4: Período de Pagamento Taxa de Performance | AI4: Período de Apuração Taxa de Performance | AJ4: Benchmark | AK4: Data de Início | AL4: Página do Fundo Plataforma XP | AM4: Mês | AN4: Ano | AO4: 12 Meses | AP4: 24 Meses (Anualizado) | AQ4: 36 Meses (Anualizado) | AR4: 2024 | AS4: 2023 | AT4: 2022 | AU4: 2021 | AV4: 2020 | AW4: Desde Início (Anualizado) | AX4: Mês | AY4: Ano | AZ4: 12 Meses | BA4: 24 Meses | BB4: 36 Meses | BC4: 2024 | BD4: 2023 | BE4: 2022 | BF4: 2021 | BG4: 2020 | BH4: Desde Início | BI4: Mês | BJ4: Ano | BK4: 12 Meses | BL4: 24 Meses (Anualizado) | BM4: 36 Meses (Anualizado) | BN4: 2024 | BO4: 2023 | BP4: 2022 | BQ4: 2021 | BR4: 2020 | BS4: Desde Início (Anualizado) | BT4: Volatilidade 12 meses | BU4: Volatilidade desde início | BV4: Sharpe 12 meses | BW4: Sharpe desde início | BX4: Máx Drawdown 12 meses | BY4: Máx Drawdown desde início | BZ4: Beta (Ibovespa) | CA4: Correlação 12M Ibovespa | CB4: Correlação 12M Dólar | CC4: Correlação 12M IRF-M | CD4: Correlação 12M IMA-B | CE4: Correlação 12M S&P | CF4: Correlação 12M IHFA | CG4: Cota Fechamento | CH4: Taxa de Administração | CI4: Taxa de Performance | CJ4: Taxa de Administração x Comissão | CK4: Taxa de Performance x Comissão*** | CL4: Margem Total (Margem Taxa Adm + Margem Taxa Perf) | CM4: PL (em milhares) | CN4: PL Médio (12 Meses - em milhares) | CO4: Captação Líquida (6 meses - em milhares) | CP4: % em Debêntures | CQ4: % em Títulos de Instituições Financeiras | CR4: % em Estruturados | CS4: % Investimentos no exterior | CT4: Enquadrado 3792 | CU4: Enquadrado 3922 | CV4: ISIN | CW4: ESG | CX4: Janela de Movimentação
B5: 9599346000122 | C5: 4UM Marlim Dividendos FIF CIA RL | D5: 27 | F5: «««« | G5: 4UM Investimentos | H5: BEM DTVM | I5: Banco Bradesco | J5: PriceWaterhouseCoopers | K5: Intranet | L5: Investidores em geral | M5: Ações | N5: Ações Dividendos | O5: Renda Variável Dividendos | P5: Renda Variavel | Q5: 500 | R5: ABERTO | S5: - | T5: 100 | U5: 500 | V5: Fechamento | W5: D+1 (útil) | X5: D+1 (útil) | Y5: D+3 (útil) | Z5: 4 | AA5: - | AB5: - | AC5: - | AD5: 0.02 | AE5: - | AF5: 0.02 | AG5: 0.2 | AH5: Junho / Dezembro | AI5: Maio / Novembro | AJ5: Ibovespa | AK5: 39629 | AL5: https://www.xpi.com.br/investimentos/fundos-de-investimento/lista/#/detalhes/b11fe7a5-44a7-488f-9c10-2cff35186866 | AM5: -0.0084006757 | AN5: 0.11285761 | AO5: 0.29160273 | AP5: 0.17381359 | AQ5: 0.18707523 | AR5: -0.087758255 | AS5: 0.26069811 | AT5: 0.043907817 | AU5: - | AV5: - | AW5: 0.10335676 | AX5: - | AY5: 2.4857217 | AZ5: 1.9666357 | BA5: 1.3482149 | BB5: 1.5326185 | BC5: - | BD5: 1.9980787 | BE5: 0.35486789 | BF5: - | BG5: - | BH5: 1.0831707 | BI5: -0.019310057 | BJ5: 0.067455258 | BK5: 0.14332783 | BL5: 0.039765666 | BM5: 0.057940389 | BN5: -0.19649798 | BO5: 0.13022372 | BP5: -0.079822219 | BQ5: - | BR5: - | BS5: 0.007244887 | BT5: 0.15042098 | BU5: 0.16505198 | BV5: 0.85756606 | BW5: 0.10539394 | BX5: -0.086724289 | BY5: -0.43109156 | BZ5: 0.53800416 | CA5: 0.96599763 | CB5: -0.45689983 | CC5: 0.64035535 | CD5: 0.52624838 | CE5: 0.075749626 | CF5: 0.75027795 | CG5: 5.7486298 | CH5: 0.3 | CI5: 0.15 | CJ5: 0.006 | CK5: - | CL5: 0.006 | CM5: 3.9450161e+08 | CN5: 3.8356248e+08 | CO5: -8663162.9 | CP5: - | CQ5: - | CR5: - | CS5: - | CT5: - | CU5: - | CV5: BRMRL2CTF002 | CW5: - | CX5: 25569.605
B6: 57832914000136 | C6: A1 CP High Grade FIF CIC RF CP RL | D6: 11 | G6: Asset1 Investimentos | H6: Intrag DTVM | I6: Itaú Unibanco | J6: PriceWaterhouseCoopers | K6: Geral | L6: Investidores em geral | M6: Renda Fixa | N6: Renda Fixa Duração Livre Crédito Livre | O6: Crédito Liquidez | P6: Longo Prazo | Q6: 1000 | R6: ABERTO | S6: - | T6: 1000 | U6: 1000 | V6: Fechamento | W6: D+0 | X6: D+0 | Y6: D+1 (útil) | Z6: 1 | AA6: - | AB6: - | AC6: A1 HIGH GRADE PÓS FIXADO FEEDER 2 RESP LIMITADA FIF CIC RENDA FIXA CRÉDITO PRIVADO | AD6: 0.005 | AE6: 0.105 | AF6: 0.006 | AG6: - | AH6: - | AI6: - | AJ6: CDI | AK6: 45625 | AL6: https://www.xpi.com.br/investimentos/fundos-de-investimento/lista/#/detalhes/0adbff9b-6e7c-4515-8826-d9a6e6c43893 | AM6: 0.010723758 | AN6: 0.045660662 | AO6: 0.15599284 | AP6: - | AQ6: - | AR6: - | AS6: - | AT6: - | AU6: - | AV6: - | AW6: 0.15352629 | AX6: 0.98298494 | AY6: 1.0056894 | AZ6: 1.0520515 | BA6: - | BB6: - | BC6: - | BD6: - | BE6: - | BF6: - | BG6: - | BH6: 1.0771725 | BI6: -0.00018562377 | BJ6: 0.0002583099 | BK6: 0.0077179371 | BL6: - | BM6: - | BN6: - | BO6: - | BP6: - | BQ6: - | BR6: - | BS6: 0.0096270606 | BT6: 0.0016027736 | BU6: 0.0026532838 | BV6: 4.1826778 | BW6: 3.5213098 | BX6: - | BY6: -0.0011436232 | BZ6: 0.0011677381 | CA6: 0.041200549 | CB6: 0.0050054695 | CC6: 0.049607247 | CD6: 0.017265598 | CE6: 0.051436676 | CF6: 0.040127344 | CG6: 1.2218686 | CH6: 0.22 | CI6: - | CJ6: 0.0011 | CK6: - | CL6: 0.0011 | CM6: 1.1502631e+09 | CN6: 5.9815283e+08 | CO6: 8.8855885e+08 | CP6: - | CQ6: - | CR6: - | CS6: - | CT6: - | CU6: - | CV6: BR0MD5CTF000 | CW6: - | CX6: 25569.626
B7: 38452175000102 | C7: A1 Hedge Advisory FIC FIM | D7: 13 | G7: Asset1 Investimentos | H7: XP Investimentos | I7: Banco Bradesco | J7: KPMG | K7: Geral | L7: Investidores em geral | M7: Multimercado | N7: Multimercados Livre | O7: Macro Alta Vol | P7: Longo Prazo: Haverá cobrança de IR no último dia útil dos meses de maio e novembro de cada ano sob a alíquota de 15% (“come-cotas”), ou no resgate, se ocorrido em data anterior, seguindo tabela regressiva partindo de 22,5% para intervalo entre aplicação e resgate menor do que 6 meses à 15% se o intervalo entre aplicação e resgate for maior do que 2 anos._x000D_ | Q7: 5000 | R7: ABERTO | S7: - | T7: 1000 | U7: 5000 | V7: Fechamento | W7: D+1 (útil) | X7: D+30 (corridos) | Y7: D+1 (útil) | Z7: 31 | AA7: - | AB7: - | AC7: A1 HEDGE ADVISORY FIC MULTIMERCADO | AD7: 0.02 | AE7: 0.12 | AF7: 0.021 | AG7: 0.2 | AH7: Maio / Novembro | AI7: Abril / Outubro | AJ7: CDI | AK7: 44113 | AL7: https://www.xpi.com.br/investimentos/fundos-de-investimento/lista/#/detalhes/df6d36ef-06c6-445e-9c67-f77ad0c79157 | AM7: 0.016625283 | AN7: 0.041471468 | AO7: 0.10043334 | AP7: 0.14486541 | AQ7: 0.098774291 | AR7: 0.077484659 | AS7: 0.080454883 | AT7: -0.013347758 | AU7: - | AV7: - | AW7: 0.05446783 | AX7: 1.5239436 | AY7: 0.91342113 | AZ7: 0.67734546 | BA7: 1.1087097 | BB7: 0.74392365 | BC7: 0.71256991 | BD7: 0.61663351 | BE7: - | BF7: - | BG7: - | BH7: 0.44559858 | BI7: 0.005715901 | BJ7: -0.0039308842 | BK7: -0.047841572 | BL7: 0.012562688 | BM7: -0.030015215 | BN7: -0.03125507 | BO7: -0.050019511 | BP7: -0.13707779 | BQ7: - | BR7: - | BS7: -0.060386064 | BT7: 0.055295734 | BU7: 0.04564062 | BV7: -0.74251563 | BW7: -1.066462 | BX7: -0.023904051 | BY7: -0.07357298 | BZ7: 0.03972513 | CA7: 0.37368354 | CB7: -0.24655291 | CC7: 0.59007014 | CD7: 0.3979232 | CE7: 0.0071997882 | CF7: 0.54502679 | CG7: 1.3406739 | CH7: 0.2 | CI7: 0.1 | CJ7: 0.004 | CK7: - | CL7: 0.004 | CM7: 5071423.8 | CN7: 5051823.5 | CO7: -3592.7 | CP7: - | CQ7: - | CR7: - | CS7: - | CT7: - | CU7: - | CV7: BR05FVCTF004 | CW7: - | CX7: 25569.626
B8: 29813769000100 | C8: Absolute Alpha Global Advisory FIC de FIF Multimercado RL | D8: 13 | F8: ««« | G8: Absolute Investimentos | H8: BNY Mellon Serviços Financeiros | I8: BNY Mellon Banco | J8: Deloitte Touche Tohmatsu | K8: Geral | L8: Investidores em geral | M8: Multimercado | N8: Multimercados Estratégia Específica | O8: Multiestratégia | P8: Longo Prazo - Alíquota regressiva de IR de 22,5% a 15,0% incidida sobre o lucro obtido no momento do resgate. | Q8: 500 | R8: ABERTO | S8: - | T8: 100 | U8: 500 | V8: Fechamento | W8: D+0 | X8: D+17 (corridos) | Y8: D+1 (útil) | Z8: 18 | AA8: Sim | AB8: 0.05 | AC8: ABSOLUTE ALPHA GLOBAL ADVISORY RESP LIMITADA FIF CIC MULTIMERCADO | AD8: 0.019 | AE8: 0.119 | AF8: 0.025 | AG8: 0.2 | AH8: Janeiro / Julho | AI8: Junho | AJ8: CDI | AK8: 43643 | AL8: https://www.xpi.com.br/investimentos/fundos-de-investimento/lista/#/detalhes/588ae6d7-d7c7-4816-a791-fc175e63b863 | AM8: 0.013556663 | AN8: 0.054636339 | AO8: 0.17691959 | AP8: 0.14860262 | AQ8: 0.13033214 | AR8: 0.094370117 | AS8: 0.10553207 | AT8: 0.11031521 | AU8: - | AV8: - | AW8: 0.094675011 | AX8: 1.242661 | AY8: 1.2033812 | AZ8: 1.1931863 | BA8: 1.1392936 | BB8: 1.0118593 | BC8: 0.86785316 | BD8: 0.80883355 | BE8: 0.89157987 | BF8: - | BG8: - | BH8: 0.99591635 | BI8: 0.0026472817 | BJ8: 0.0092339868 | BK8: 0.028644686 | BL8: 0.016072251 | BM8: 0.0013532297 | BN8: -0.014369611 | BO8: -0.024942327 | BP8: -0.013414826 | BQ8: - | BR8: - | BS8: -0.00035450445 | BT8: 0.01906009 | BU8: 0.016700956 | BV8: 1.3029939 | BW8: -0.0084496382 | BX8: -0.0029350231 | BY8: -0.010985557 | BZ8: 0.020073714 | CA8: 0.1282095 | CB8: -0.085371103 | CC8: 0.11409053 | CD8: 0.1247656 | CE8: 0.1314564 | CF8: 0.16710669 | CG8: 1.8534514 | CH8: 0.24 | CI8: 0.15 | CJ8: 0.00456 | CK8: 0.0007483753 | CL8: 0.0053083753 | CM8: 78525437 | CN8: 71616064 | CO8: 3922529 | CP8: - | CQ8: - | CR8: - | CS8: - | CT8: - | CU8: - | CV8: BR01VGCTF001 | CW8: - | CX8: 25569.626
B9: 35617938000130 | C9: Absolute Alpha Marb Advisory FIC de FIF Multimercado RL | D9: 13 | G9: Absolute Investimentos | H9: BNY Mellon Serviços Financeiros | I9: BNY Mellon Banco | J9: Deloitte Touche Tohmatsu | K9: Geral | L9: Investidores qualificados | M9: Multimercado | N9: Multimercados Estratégia Específica | O9: Internacional Multimercado Hedgeado | P9: Renda Variável | Q9: 500 | R9: ABERTO | S9: - | T9: 100 | U9: 100 | V9: Fechamento | W9: D+0 | X9: D+17 (corridos) | Y9: D+1 (útil) | Z9: 18 | AA9: Sim | AB9: 0.05 | AC9: ABSOLUTE ALPHA MARB ADVISORY RESP LIMITADA FIF CIC MULTIMERCADO | AD9: 0.019 | AE9: 0.119 | AF9: 0.025 | AG9: 0.2 | AH9: Janeiro / Julho | AI9: Junho | AJ9: CDI | AK9: 43826 | AL9: https://www.xpi.com.br/investimentos/fundos-de-investimento/lista/#/detalhes/1f560d4a-7821-4d7c-863c-1241e3dc34aa | AM9: 0.010260181 | AN9: 0.048890008 | AO9: 0.1917215 | AP9: 0.16598451 | AQ9: 0.13196123 | AR9: 0.089496743 | AS9: 0.083924701 | AT9: 0.11367809 | AU9: - | AV9: - | AW9: 0.10308012 | AX9: 0.94049157 | AY9: 1.0768166 | AZ9: 1.2930138 | BA9: 1.2828503 | BB9: 1.0261047 | BC9: 0.82303629 | BD9: 0.64322737 | BE9: 0.91875909 | BF9: - | BG9: - | BH9: 1.0628238 | BI9: -0.00064920019 | BJ9: 0.0034876554 | BK9: 0.043446588 | BL9: 0.032404505 | BM9: 0.0029746259 | BN9: -0.019242986 | BO9: -0.046549692 | BP9: -0.010051941 | BQ9: - | BR9: - | BS9: 0.0055543927 | BT9: 0.026932105 | BU9: 0.046769416 | BV9: 1.3931937 | BW9: 0.11688901 | BX9: -0.0063213971 | BY9: -0.04965034 | BZ9: 0.046310218 | CA9: 0.18974423 | CB9: -0.093167161 | CC9: 0.19723617 | CD9: 0.18071179 | CE9: 0.2344724 | CF9: 0.25437621 | CG9: 1.8570785 | CH9: 0.25 | CI9: 0.1 | CJ9: 0.00475 | CK9: 0.00075672799 | CL9: 0.005506728 | CM9: 76282294 | CN9: 39060432 | CO9: 47084385 | CP9: - | CQ9: - | CR9: - | CS9: - | CT9: - | CU9: - | CV9: BR03JGCTF002 | CW9: - | CX9: 25569.626
B10: 48096589000108 | C10: Absolute Atenas Advisory FIC FIF RF CP RL | D10: 2 | G10: Absolute Investimentos | H10: BTG Pactual Serviços Financeiros | I10: Banco BTG Pactual | J10: KPMG | K10: Geral | L10: Investidores em geral | M10: Renda Fixa | N10: Renda Fixa Duração Baixa Grau de Investimento | O10: Crédito Liquidez | P10: Longo Prazo | Q10: 500 | R10: ABERTO | S10: - | T10: 100 | U10: 500 | V10: Fechamento | W10: D+0 | X10: D+0 | Y10: D+1 (útil) | Z10: 1 | AA10: - | AB10: - | AC10: ABSOLUTE ATENAS ADVISORY FIF CIC RENDA FIXA | AD10: 0.0038 | AE10: 0.1038 | AF10: 0.005 | AG10: - | AH10: - | AI10: - | AJ10: CDI | AK10: 44862 | AL10: https://www.xpi.com.br/investimentos/fundos-de-investimento/lista/#/detalhes/baca96c2-efdc-4475-9709-ccafcef26bf2 | AM10: 0.0099284704 | AN10: 0.040944578 | AO10: 0.14428765 | AP10: 0.13305777 | AQ10: 0.13655073 | AR10: 0.12135209 | AS10: 0.13834874 | AT10: - | AU10: - | AV10: - | AW10: 0.13675077 | AX10: 0.91008554 | AY10: 0.90181623 | AZ10: 0.97310903 | BA10: 1.0127353 | BB10: 1.0664582 | BC10: 1.1159867 | BD10: 1.0603517 | BE10: - | BF10: - | BG10: - | BH10: 1.060327 | BI10: -0.00098091109 | BJ10: -0.0044577743 | BK10: -0.0039872566 | BL10: 0.001478912 | BM10: 0.0075435113 | BN10: 0.012612363 | BO10: 0.00787435 | BP10: - | BQ10: - | BR10: - | BS10: 0.0068915821 | BT10: 0.0024692505 | BU10: 0.0026418575 | BV10: -1.4082336 | BW10: 2.2517581 | BX10: -0.0014617527 | BY10: -0.001863807 | BZ10: -0.00053221391 | CA10: -0.0506346 | CB10: 0.019724236 | CC10: -0.027907364 | CD10: -0.016904922 | CE10: 0.079036145 | CF10: -0.024603488 | CG10: 1.5629491 | CH10: 0.3 | CI10: - | CJ10: 0.00114 | CK10: - | CL10: 0.00114 | CM10: 7.4588501e+08 | CN10: 9.397011e+08 | CO10: -5.282368e+08 | CP10: - | CQ10: - | CR10: - | CS10: - | CT10: - | CU10: - | CV10: BR0DVYCTF005 | CW10: - | CX10: 25569.626
B11: 48122126000165 | C11: Absolute Creta Advisory FIF FIRF | D11: 2 | G11: Absolute Investimentos | H11: BTG Pactual Serviços Financeiros | I11: Banco BTG Pactual | J11: KPMG | K11: Geral | L11: Investidores em geral | M11: Renda Fixa | N11: Renda Fixa Duração Baixa Grau de Investimento | O11: Crédito High Grade | P11: Longo Prazo | Q11: 500 | R11: FECHADO | S11: - | T11: 100 | U11: 500 | V11: Fechamento | W11: D+0 | X11: D+30 (corridos) | Y11: D+1 (útil) | Z11: 31 | AA11: - | AB11: - | AC11: ABSOLUTE CRETA ADVISORY FIF CIC RENDA FIXA | AD11: 0.0058 | AE11: 0.1058 | AF11: 0.007 | AG11: - | AH11: - | AI11: - | AJ11: CDI | AK11: 44862 | AL11: https://www.xpi.com.br/investimentos/fundos-de-investimento/lista/#/detalhes/9882ecb0-c421-47a2-99fb-f0b74d7f7b78 | AM11: 0.0083405799 | AN11: 0.033699826 | AO11: 0.13657197 | AP11: 0.13275738 | AQ11: 0.14080476 | AR11: 0.13047871 | AS11: 0.14185645 | AT11: - | AU11: - | AV11: - | AW11: 0.13996014 | AX11: 0.7645328 | AY11: 0.74224846 | AZ11: 0.92107268 | BA11: 1.0103066 | BB11: 1.1041541 | BC11: 1.1999176 | BD11: 1.0872359 | BE11: - | BF11: - | BG11: - | BH11: 1.0893864 | BI11: -0.0025688015 | BJ11: -0.011702526 | BK11: -0.011702942 | BL11: 0.0011970279 | BM11: 0.011779823 | BN11: 0.021738984 | BO11: 0.011382055 | BP11: - | BQ11: - | BR11: - | BS11: 0.010176573 | BT11: 0.0053903065 | BU11: 0.0048349208 | BV11: -1.8987752 | BW11: 1.8154965 | BX11: -0.0036213204 | BY11: -0.0036420568 | BZ11: -0.00022159028 | CA11: -0.039824209 | CB11: 0.0083930284 | CC11: -0.0035472962 | CD11: -0.0096471518 | CE11: 0.089192243 | CF11: -0.0096814975 | CG11: 1.5783773 | CH11: 0.3 | CI11: - | CJ11: 0.00174 | CK11: - | CL11: 0.00174 | CM11: 1.7868424e+09 | CN11: 2.0350439e+09 | CO11: -4.4727944e+08 | CP11: - | CQ11: - | CR11: - | CS11: - | CT11: - | CU11: - | CV11: BR0DWGCTF000 | CW11: - | CX11: 25569.626
B12: 18860059000115 | C12: Absolute Hedge FIC de FIF Multimercado RL | D12: 13 | F12: «««« | G12: Absolute Investimentos | H12: BTG Pactual Serviços Financeiros | I12: Banco BTG Pactual | J12: KPMG | K12: Geral | L12: Investidores em geral | M12: Multimercado | N12: Multimercados Macro | O12: Macro Média Vol | P12: Longo Prazo - Alíquota regressiva de IR de 22,5% a 15,0% incidida sobre o lucro obtido no momento do resgate. | Q12: 500 | R12: ABERTO | S12: - | T12: 500 | U12: 500 | V12: Fechamento | W12: D+0 | X12: D+4 (corridos) | Y12: D+1 (útil) | Z12: 5 | AA12: - | AB12: - | AC12: ABSOLUTE HEDGE FIF CIC MULTIMERCADO | AD12: 0.019 | AE12: 0.119 | AF12: 0.025 | AG12: 0.2 | AH12: Janeiro / Julho | AI12: Junho | AJ12: CDI | AK12: 41547 | AL12: https://www.xpi.com.br/investimentos/fundos-de-investimento/lista/#/detalhes/313c7545-362f-4755-a456-9b1166649079 | AM12: 0.014760901 | AN12: 0.042951149 | AO12: 0.10868789 | AP12: 0.11079765 | AQ12: 0.11523619 | AR12: 0.089877753 | AS12: 0.12721061 | AT12: 0.16584597 | AU12: - | AV12: - | AW12: 0.10815167 | AX12: 1.3530465 | AY12: 0.94601153 | AZ12: 0.73301605 | BA12: 0.83450752 | BB12: 0.88179679 | BC12: 0.82654017 | BD12: 0.97498528 | BE12: 1.3403857 | BF12: - | BG12: - | BH12: 1.1515488 | BI12: 0.0038515195 | BJ12: -0.0024512035 | BK12: -0.03958702 | BL12: -0.019397099 | BM12: -0.013661822 | BN12: -0.018861975 | BO12: -0.0032637801 | BP12: 0.042115936 | BQ12: - | BR12: - | BS12: 0.013011236 | BT12: 0.025115028 | BU12: 0.029547167 | BV12: -1.3850777 | BW12: 0.28523815 | BX12: -0.0090735864 | BY12: -0.046284828 | BZ12: 0.041335455 | CA12: 0.62072976 | CB12: -0.53332857 | CC12: 0.59687909 | CD12: 0.49472878 | CE12: 0.052228804 | CF12: 0.82973216 | CG12: 3.6216455 | CH12: 0.27 | CI12: 0.15 | CJ12: 0.00513 | CK12: - | CL12: 0.00513 | CM12: 3.4455302e+08 | CN12: 3.7093944e+08 | CO12: -80664151 | CP12: - | CQ12: - | CR12: - | CS12: - | CT12: - | CU12: - | CV12: BRABH1CTF002 | CW12: - | CX12: 25569.626
B13: 57027498000101 | C13: Absolute Hidra CDI Plus Advisory FIC FI Infra RF CP RL | D13: 12 | G13: ABSOLUTE DHAMA GESTÃO DE INVESTIMENTOS LTDA | H13: BTG Pactual Serviços Financeiros | I13: Banco BTG Pactual | J13: KPMG | K13: Geral | L13: Investidores em geral | M13: Renda Fixa | N13: Renda Fixa Duração Livre Crédito Livre | O13: Debêntures Incentivadas Hedgeado | P13: Debêntures incentivadas | Q13: 500 | R13: ABERTO | S13: - | T13: 100 | U13: 100 | V13: Fechamento | W13: D+0 | X13: D+30 (corridos) | Y13: D+1 (útil) | Z13: 31 | AA13: - | AB13: - | AC13: ABSOLUTE HIDRA CDI PLUS ADVISORY FIC INFRA RENDA FIXA | AD13: 0.0068 | AE13: 0.1068 | AF13: 0.008 | AG13: 0.2 | AH13: Dezembro / Junho | AI13: Novembro / Maio | AJ13: CDI | AK13: 45735 | AL13: https://www.xpi.com.br/investimentos/fundos-de-investimento/lista/#/detalhes/c203a0e2-29bd-4189-912b-cdfb7a61aaf5 | AM13: -0.00090936574 | AN13: 0.02312087 | AO13: 0.12682825 | AP13: - | AQ13: - | AR13: - | AS13: - | AT13: - | AU13: - | AV13: - | AW13: 0.12694635 | AX13: - | AY13: 0.50924388 | AZ13: 0.85535884 | BA13: - | BB13: - | BC13: - | BD13: - | BE13: - | BF13: - | BG13: - | BH13: 0.85940091 | BI13: -0.011818747 | BJ13: -0.022281482 | BK13: -0.021446655 | BL13: - | BM13: - | BN13: - | BO13: - | BP13: - | BQ13: - | BR13: - | BS13: -0.018095597 | BT13: 0.0094098631 | BU13: 0.0094071288 | BV13: -1.9999716 | BW13: -1.9231268 | BX13: -0.0053445715 | BY13: -0.0053445715 | BZ13: -0.010401588 | CA13: -0.189304 | CB13: 0.036133092 | CC13: -0.32753858 | CD13: -0.37038677 | CE13: -0.11468103 | CF13: -0.25819929 | CG13: 1.142011 | CH13: 0.24 | CI13: 0.15 | CJ13: 0.001632 | CK13: - | CL13: 0.001632 | CM13: 5.9994398e+08 | CN13: 6.1757857e+08 | CO13: 32477930 | CP13: - | CQ13: - | CR13: - | CS13: - | CT13: - | CU13: - | CV13: BR0LJGCTF000 | CW13: - | CX13: 25569.626
B14: 51112363000150 | C14: Absolute Hidra IPCA FIC de FIF RF Investimento em Infra CP | D14: 12 | G14: ABSOLUTE DHAMA GESTÃO DE INVESTIMENTOS LTDA | H14: BTG Pactual Serviços Financeiros | I14: Banco BTG Pactual | J14: KPMG | K14: Geral | L14: Investidores em geral | M14: Renda Fixa | N14: Renda Fixa Duração Livre Crédito Livre | O14: Debêntures Incentivadas Não Hedgeado | P14: Debêntures Incentivadas | Q14: 500 | R14: ABERTO | S14: - | T14: 100 | U14: 500 | V14: Fechamento | W14: D+0 | X14: D+30 (corridos) | Y14: D+1 (útil) | Z14: 31 | AA14: - | AB14: - | AC14: ABSOLUTE HIDRA IPCA FIC INFRA RENDA FIXA | AD14: 0.0068 | AE14: 0.1068 | AF14: 0.008 | AG14: 0.2 | AH14: - | AI14: - | AJ14: IMA-B 5 | AK14: 45105 | AL14: https://www.xpi.com.br/investimentos/fundos-de-investimento/lista/#/detalhes/a61efa6a-a0aa-4a16-a4e0-cccd5f92302a | AM14: -0.0037947649 | AN14: 0.024636642 | AO14: 0.095214659 | AP14: 0.095863714 | AQ14: - | AR14: 0.089215754 | AS14: - | AT14: - | AU14: - | AV14: - | AW14: 0.10860031 | AX14: - | AY14: 0.54262921 | AZ14: 0.64214951 | BA14: 0.71691948 | BB14: - | BC14: 0.82045224 | BD14: - | BE14: - | BF14: - | BG14: - | BH14: 0.83038862 | BI14: -0.014704146 | BJ14: -0.02076571 | BK14: -0.053060248 | BL14: -0.033387933 | BM14: - | BN14: -0.019523974 | BO14: - | BP14: - | BQ14: - | BR14: - | BS14: -0.019616683 | BT14: 0.016664722 | BU14: 0.019820899 | BV14: -2.8319465 | BW14: -0.88901406 | BX14: -0.0077784872 | BY14: -0.014611564 | BZ14: 0.051701136 | CA14: 0.40713154 | CB14: -0.31970613 | CC14: 0.52151531 | CD14: 0.60094846 | CE14: -0.09620398 | CF14: 0.44834028 | CG14: 1.3387048 | CH14: 0.24 | CI14: 0.15 | CJ14: 0.001632 | CK14: - | CL14: 0.001632 | CM14: 2.556526e+08 | CN14: 2.4323291e+08 | CO14: 12365234 | CP14: - | CQ14: - | CR14: - | CS14: - | CT14: - | CU14: - | CV14: BR0FWYCTF008 | CW14: - | CX14: 25569.605
B15: 32892827000143 | C15: Absolute Pace Long Biased Advisory FIC FIA | D15: 26 | F15: ««««« | G15: Absolute Investimentos | H15: BNY Mellon Serviços Financeiros | I15: BNY Mellon Banco | J15: Deloitte Touche Tohmatsu | K15: Geral | L15: Investidores qualificados | M15: Ações | N15: Ações Livre | O15: Renda Variável Long Biased | P15: Renda Variável - Alíquota de IR de 15% incidida sobre o lucro obtido no momento do resgate. | Q15: 500 | R15: FECHADO | S15: - | T15: 100 | U15: 100 | V15: Fechamento | W15: D+1 (útil) | X15: D+30 (corridos) | Y15: D+3 (útil) | Z15: 33 | AA15: Sim | AB15: 0.1 | AC15: ABSOLUTE PACE LONG BIASED ADVISORY FIF CIC AÇÕES | AD15: 0.019 | AE15: 0.119 | AF15: 0.022 | AG15: 0.2 | AH15: Janeiro / Julho | AI15: Junho | AJ15: - | AK15: 43643 | AL15: https://www.xpi.com.br/investimentos/fundos-de-investimento/lista/#/detalhes/26cc40f4-f74b-4648-91af-8069a4428d36 | AM15: 0.014986112 | AN15: 0.096777388 | AO15: 0.31900756 | AP15: 0.19569167 | AQ15: 0.23440183 | AR15: -0.046991314 | AS15: 0.27733871 | AT15: 0.1503283 | AU15: - | AV15: - | AW15: 0.18882912 | AX15: 1.3736904 | AY15: 2.1315501 | AZ15: 2.1514602 | BA15: 1.5331928 | BB15: 2.00681 | BC15: - | BD15: 2.1256179 | BE15: 1.2149702 | BF15: - | BG15: - | BH15: 2.6302932 | BI15: 0.0040767308 | BJ15: 0.051375036 | BK15: 0.17073265 | BL15: 0.060351861 | BM15: 0.10529933 | BN15: -0.15573104 | BO15: 0.14686431 | BP15: 0.026598265 | BQ15: - | BR15: - | BS15: 0.10919953 | BT15: 0.14840707 | BU15: 0.18559832 | BV15: 1.008833 | BW15: 0.53669998 | BX15: -0.067236009 | BY15: -0.4033713 | BZ15: 0.71925183 | CA15: 0.87341979 | CB15: -0.4810344 | CC15: 0.63573886 | CD15: 0.56229871 | CE15: 0.095517901 | CF15: 0.75106892 | CG15: 3.2540322 | CH15: 0.24 | CI15: 0.15 | CJ15: 0.00456 | CK15: - | CL15: 0.00456 | CM15: 7.3504333e+08 | CN15: 7.02772e+08 | CO15: 9864917.1 | CP15: - | CQ15: - | CR15: - | CS15: - | CT15: - | CU15: - | CV15: BR01VHCTF009 | CW15: - | CX15: 25569.626
B16: 28947266000165 | C16: Absolute Vertex Advisory FIC FIF Multimercado RL | D16: 13 | E16: Sim | F16: ««««« | G16: Absolute Investimentos | H16: BNY Mellon Serviços Financeiros | I16: BNY Mellon Banco | J16: Deloitte Touche Tohmatsu | K16: Geral | L16: Investidores em geral | M16: Multimercado | N16: Multimercados Macro | O16: Macro Alta Vol | P16: Longo Prazo - Alíquota regressiva de IR de 22,5% a 15,0% incidida sobre o lucro obtido no momento do resgate. | Q16: 500 | R16: ABERTO | S16: - | T16: 100 | U16: 100 | V16: Fechamento | W16: D+0 | X16: D+44 (corridos) | Y16: D+1 (útil) | Z16: 45 | AA16: Sim | AB16: 0.05 | AC16: ABSOLUTE VERTEX ADVISORY RESP LIMITADA FIF CIC MULTIMERCADO | AD16: 0.019 | AE16: 0.119 | AF16: 0.025 | AG16: 0.2 | AH16: Janeiro / Julho | AI16: Junho | AJ16: CDI | AK16: 43416 | AL16: https://www.xpi.com.br/investimentos/fundos-de-investimento/lista/#/detalhes/eaaccb10-fa3d-4e1b-8c85-1f30a3df17b2 | AM16: 0.019782088 | AN16: 0.046793581 | AO16: 0.092004177 | AP16: 0.11200284 | AQ16: 0.12244471 | AR16: 0.092206393 | AS16: 0.142031 | AT16: 0.22970151 | AU16: - | AV16: - | AW16: 0.11309996 | AX16: 1.8133098 | AY16: 1.0306422 | AZ16: 0.62049728 | BA16: 0.8440664 | BB16: 0.94346713 | BC16: 0.84795497 | BD16: 1.0885737 | BE16: 1.8564733 | BF16: - | BG16: - | BH16: 1.3113356 | BI16: 0.0088727066 | BJ16: 0.0013912291 | BK16: -0.056270731 | BL16: -0.018267511 | BM16: -0.0064941122 | BN16: -0.016533335 | BO16: 0.011556605 | BP16: 0.10597147 | BQ16: - | BR16: - | BS16: 0.02472 | BT16: 0.049834448 | BU16: 0.044780263 | BV16: -0.98389362 | BW16: 0.44204246 | BX16: -0.024261926 | BY16: -0.052435698 | BZ16: 0.086173083 | CA16: 0.62073321 | CB16: -0.52900794 | CC16: 0.60523281 | CD16: 0.50411139 | CE16: 0.059812842 | CF16: 0.83443992 | CG16: 2.2184605 | CH16: 0.25 | CI16: 0.15 | CJ16: 0.00475 | CK16: - | CL16: 0.00475 | CM16: 1.1437434e+09 | CN16: 1.2338967e+09 | CO16: -2.7242716e+08 | CP16: - | CQ16: - | CR16: - | CS16: - | CT16: - | CU16: - | CV16: BR00M8CTF005 | CW16: - | CX16: 25569.626
B17: 34258751000124 | C17: Absoluto Partners Advisory FIF em Cotas FIA RL | D17: 39 | F17: « | G17: Absoluto Partners Investimentos | H17: BTG Pactual Serviços Financeiros | I17: Banco BTG Pactual | J17: PriceWaterhouseCoopers | K17: Intranet | L17: Investidores qualificados | M17: Ações | N17: Ações Livre | O17: Renda Variável Long Only | P17: Renda Variável - Alíquota de IR de 15% incidida sobre o lucro obtido no momento do resgate. | Q17: 50000 | R17: FECHADO | S17: - | T17: 10000 | U17: 50000 | V17: Fechamento | W17: D+1 (útil) | X17: D+60 (corridos) | Y17: D+2 (útil) | Z17: 62 | AA17: - | AB17: - | AC17: ABSOLUTO PARTNERS ADVISORY FIF CIC AÇÕES | AD17: 0.0185 | AE17: 0.0585 | AF17: 0.0194 | AG17: 0.2 | AH17: - | AI17: - | AJ17: - | AK17: 43703 | AL17: https://www.xpi.com.br/investimentos/fundos-de-investimento/lista/#/detalhes/dc67fe3e-8fd3-436c-b956-5fe86e146109 | AM17: 0.015355349 | AN17: 0.088334691 | AO17: 0.38592236 | AP17: 0.21806237 | AQ17: 0.21997368 | AR17: -0.1966981 | AS17: 0.28471675 | AT17: -0.13546567 | AU17: - | AV17: - | AW17: 0.10596417 | AX17: 1.4075362 | AY17: 1.9455972 | AZ17: 2.6027489 | BA17: 1.7258679 | BB17: 1.8583087 | BC17: - | BD17: 2.1821657 | BE17: - | BF17: - | BG17: - | BH17: 1.138703 | BI17: 0.0044459673 | BJ17: 0.042932339 | BK17: 0.23764745 | BL17: 0.081424976 | BM17: 0.090846811 | BN17: -0.30543782 | BO17: 0.15424236 | BP17: -0.2591957 | BQ17: - | BR17: - | BS17: 0.011808419 | BT17: 0.19797096 | BU17: 0.25699972 | BV17: 1.0497584 | BW17: 0.16560777 | BX17: -0.099740541 | BY17: -0.47113188 | BZ17: 0.93780607 | CA17: 0.89842214 | CB17: -0.42101915 | CC17: 0.62843796 | CD17: 0.51135812 | CE17: 0.13207533 | CF17: 0.73790566 | CG17: 1.9547279 | CH17: 0.07 | CI17: - | CJ17: 0.001295 | CK17: - | CL17: 0.001295 | CM17: 1.2678276e+08 | CN17: 1.2720816e+08 | CO17: -14500730 | CP17: - | CQ17: - | CR17: - | CS17: - | CT17: - | CU17: - | CV17: BR02TYCTF006 | CW17: - | CX17: 25569.605
B18: 39992830000188 | C18: Ace Capital Absoluto FIC FIF FIA RL | D18: 26 | G18: ACE Capital | H18: BNY Mellon Serviços Financeiros | I18: BNY Mellon Banco | J18: KPMG | K18: Geral | L18: Investidores qualificados | M18: Ações | N18: Ações Livre | O18: Renda Variável Long Only | P18: Renda Variavel | Q18: 500 | R18: FECHADO | S18: - | T18: 100 | U18: 500 | V18: Fechamento | W18: D+1 (útil) | X18: D+30 (corridos) | Y18: D+2 (útil) | Z18: 32 | AA18: - | AB18: - | AC18: ACE CAPITAL ABSOLUTO RESP LIMITADA FIF CIC AÇÕES | AD18: 0.02 | AE18: 0.02 | AF18: 0.022 | AG18: 0.2 | AH18: Março / Setembro | AI18: Fevereiro / Agosto | AJ18: IMA-B | AK18: 44368 | AL18: https://www.xpi.com.br/investimentos/fundos-de-investimento/lista/#/detalhes/123ec1dc-9324-4ca4-bd21-f3d9f691dd56 | AM18: -0.017891035 | AN18: 0.051638794 | AO18: 0.27582182 | AP18: 0.15650734 | AQ18: 0.11697826 | AR18: -0.18508071 | AS18: 0.15833996 | AT18: 0.059472248 | AU18: - | AV18: - | AW18: 0.060816902 | AX18: - | AY18: 1.1373594 | AZ18: 1.8602057 | BA18: 1.2043113 | BB18: 0.89662783 | BC18: - | BD18: 1.2135711 | BE18: 0.48066137 | BF18: - | BG18: - | BH18: 0.4492834 | BI18: -0.028800417 | BJ18: 0.0062364414 | BK18: 0.12754692 | BL18: 0.023497777 | BM18: -0.011929977 | BN18: -0.29382043 | BO18: 0.027865564 | BP18: -0.064257787 | BQ18: - | BR18: - | BS18: -0.065659396 | BT18: 0.17392251 | BU18: 0.19242121 | BV18: 0.69300965 | BW18: -0.18930182 | BX18: -0.084191319 | BY18: -0.20902537 | BZ18: 0.84508966 | CA18: 0.91788566 | CB18: -0.45252067 | CC18: 0.66677169 | CD18: 0.53911882 | CE18: 0.13210993 | CF18: 0.78198555 | CG18: 133.11714 | CH18: 0.27 | CI18: 0.15 | CJ18: 0.0054 | CK18: 0.004067997 | CL18: 0.009467997 | CM18: 2976715.8 | CN18: 3244748.9 | CO18: -1870390.2 | CP18: - | CQ18: - | CR18: - | CS18: - | CT18: - | CU18: - | CV18: BR08IRCTF000 | CW18: - | CX18: 25569.626
B19: 7124064000143 | C19: Ace Capital Absoluto Institucional FIC de FIF em Ações RL | D19: 36 | G19: ACE Capital | H19: BNY Mellon Serviços Financeiros | I19: BNY Mellon Banco | J19: KPMG | K19: Geral | L19: Investidores em geral | M19: Ações | N19: Ações Livre | O19: Renda Variável Long Only | P19: Ações | Q19: 100 | R19: ABERTO | S19: - | T19: 100 | U19: 100 | V19: Fechamento | W19: D+1 (útil) | X19: D+1 (útil) | Y19: D+3 (útil) | Z19: 4 | AA19: - | AB19: - | AC19: ACE CAPITAL ABSOLUTO INSTITUCIONAL RESP LIMITADA FIF CIC AÇÕES | AD19: 0.02 | AE19: 0.02 | AF19: 0.025 | AG19: 0.2 | AH19: Julho / Janeiro | AI19: Junho | AJ19: Ibovespa | AK19: 38357 | AL19: https://www.xpi.com.br/investimentos/fundos-de-investimento/lista/#/detalhes/40b7ae9d-bd3a-4382-9268-305747654879 | AM19: -0.013499649 | AN19: 0.12251502 | AO19: 0.34137369 | AP19: 0.20543773 | AQ19: 0.21521198 | AR19: -0.058294428 | AS19: 0.1182861 | AT19: -0.089872024 | AU19: - | AV19: - | AW19: 0.13819048 | AX19: - | AY19: 2.698429 | AZ19: 2.3023025 | BA19: 1.616695 | BB19: 1.810063 | BC19: - | BD19: 0.90658477 | BE19: - | BF19: - | BG19: - | BH19: 1.9062248 | BI19: -0.024409031 | BJ19: 0.077112671 | BK19: 0.19309878 | BL19: 0.069529746 | BM19: 0.086079798 | BN19: -0.16703416 | BO19: -0.012188296 | BP19: -0.21360206 | BQ19: - | BR19: - | BS19: 0.061255479 | BT19: 0.16482922 | BU19: 0.23264445 | BV19: 1.0260828 | BW19: 0.23624467 | BX19: -0.080920805 | BY19: -0.60789348 | BZ19: 0.80954611 | CA19: 0.96765084 | CB19: -0.46902279 | CC19: 0.66206604 | CD19: 0.54138026 | CE19: 0.076024929 | CF19: 0.76470013 | CG19: 1561.9795 | CH19: 0.27 | CI19: 0.15 | CJ19: 0.0054 | CK19: - | CL19: 0.0054 | CM19: 67663262 | CN19: 61050824 | CO19: 14495360 | CP19: - | CQ19: - | CR19: - | CS19: - | CT19: - | CU19: - | CV19: BRGPFICTF005 | CW19: - | CX19: 25569.626
B20: 34774642000160 | C20: ACE Capital Advisory FIF CIC Multi RL | D20: 13 | F20: «««« | G20: ACE Capital | H20: Intrag DTVM | I20: Itaú Unibanco | J20: EY | K20: Geral | L20: Investidores em geral | M20: Multimercado | N20: Multimercados Macro | O20: Macro Média Vol | P20: Longo Prazo - Alíquota regressiva de IR de 22,5% a 15,0% incidida sobre o lucro obtido no momento do resgate. | Q20: 500 | R20: ABERTO | S20: - | T20: 100 | U20: 100 | V20: Fechamento | W20: D+0 | X20: D+30 (corridos) | Y20: D+1 (útil) | Z20: 31 | AA20: Sim | AB20: 0.1 | AC20: ACE CAPITAL ADVISORY RESP LIMITADA FIF CIC MULTIMERCADO | AD20: 0.0192 | AE20: 0.0992 | AF20: 0.022 | AG20: 0.2 | AH20: Junho / Dezembro | AI20: Maio / Novembro | AJ20: CDI | AK20: 43738 | AL20: https://www.xpi.com.br/investimentos/fundos-de-investimento/lista/#/detalhes/1a86ef5f-913f-4942-84f7-6441470f97eb | AM20: 0.015528487 | AN20: 0.022765384 | AO20: 0.12755327 | AP20: 0.13446759 | AQ20: 0.10021926 | AR20: 0.069253499 | AS20: 0.10875942 | AT20: 0.14848866 | AU20: - | AV20: - | AW20: 0.10440309 | AX20: 1.4234067 | AY20: 0.5014142 | AZ20: 0.86024851 | BA20: 1.0241423 | BB20: 0.75586186 | BC20: 0.63687394 | BD20: 0.83356909 | BE20: 1.200102 | BF20: - | BG20: - | BH20: 1.1077054 | BI20: 0.0046191055 | BJ20: -0.022636968 | BK20: -0.02072164 | BL20: 0.0028019367 | BM20: -0.028580637 | BN20: -0.039486229 | BO20: -0.021714972 | BP20: 0.024758626 | BQ20: - | BR20: - | BS20: 0.0092770359 | BT20: 0.042940252 | BU20: 0.042169674 | BV20: -0.40292243 | BW20: 0.19339105 | BX20: -0.032400966 | BY20: -0.046464961 | BZ20: 0.079572823 | CA20: 0.55369277 | CB20: -0.4121483 | CC20: 0.76899249 | CD20: 0.56099748 | CE20: 0.20370773 | CF20: 0.82340918 | CG20: 1.9174562 | CH20: 0.24 | CI20: 0.15 | CJ20: 0.004608 | CK20: - | CL20: 0.004608 | CM20: 1.7104482e+08 | CN20: 1.8141419e+08 | CO20: -20592864 | CP20: - | CQ20: - | CR20: - | CS20: - | CT20: - | CU20: - | CV20: BR02P7CTF002 | CW20: - | CX20: 25569.626
B21: 47612105000165 | C21: ACE Capital Multicenários FC FIF MULT - RL | D21: 16 | E21: Sim | G21: Ace Capital Saires Gestora de Recursos | H21: BNY Mellon Serviços Financeiros | I21: BNY Mellon Banco | J21: KPMG | K21: Geral | L21: Investidores em geral | M21: Multimercado | N21: Multimercados Trading | O21: Quantitativo | P21: Longo Prazo | Q21: 100 | R21: ABERTO | S21: - | T21: 100 | U21: 100 | V21: Fechamento | W21: D+0 | X21: D+15 (corridos) | Y21: D+2 (útil) | Z21: 17 | AA21: - | AB21: - | AC21: ACE CAPITAL MULTICENÁRIOS RESP LIMITADA FIF CIC MULTIMERCADO | AD21: 0.015 | AE21: 0.015 | AF21: 0.016 | AG21: 0.1 | AH21: Novembro / Maio | AI21: Outubro / Abril | AJ21: CDI | AK21: 44895 | AL21: https://www.xpi.com.br/investimentos/fundos-de-investimento/lista/#/detalhes/0f2d6d27-b25c-4925-ab83-32f2571b8734 | AM21: 0.032375997 | AN21: 0.070737502 | AO21: 0.33568023 | AP21: 0.28355074 | AQ21: 0.25720237 | AR21: 0.14999907 | AS21: 0.23491773 | AT21: - | AU21: - | AV21: - | AW21: 0.24409244 | AX21: 2.9677207 | AY21: 1.558014 | AZ21: 2.2639045 | BA21: 2.3104392 | BB21: 2.2486609 | BC21: 1.3794321 | BD21: 1.8004892 | BE21: - | BF21: - | BG21: - | BH21: 2.1405741 | BI21: 0.021466615 | BJ21: 0.02533515 | BK21: 0.18740533 | BL21: 0.14324496 | BM21: 0.12816284 | BN21: 0.041259338 | BO21: 0.10444334 | BP21: - | BQ21: - | BR21: - | BS21: 0.11674819 | BT21: 0.11675624 | BU21: 0.10665581 | BV21: 1.3543987 | BW21: 0.95699378 | BX21: -0.094676681 | BY21: -0.094676681 | BZ21: 0.29751904 | CA21: 0.41610856 | CB21: -0.37356871 | CC21: 0.40060716 | CD21: 0.28772724 | CE21: 0.13564782 | CF21: 0.60398275 | CG21: 2.1017173 | CH21: 0.3 | CI21: 0.15 | CJ21: 0.0045 | CK21: 0.0024480896 | CL21: 0.0069480896 | CM21: 4.1014899e+08 | CN21: 2.4175446e+08 | CO21: 2.5667764e+08 | CP21: - | CQ21: - | CR21: - | CS21: - | CT21: - | CU21: - | CV21: BR0E5ICTF007 | CW21: - | CX21: 25569.626
B22: 24078037000109 | C22: Adam Macro Advisory FIC FIF Multimercado RL | D22: 13 | F22: « | G22: Adam Capital | H22: BNY Mellon Serviços Financeiros | I22: BNY Mellon Banco | J22: Deloitte Touche Tohmatsu | K22: Geral | L22: Investidores em geral | M22: Multimercado | N22: Multimercados Macro | O22: Macro Alta Vol | P22: Longo Prazo - Alíquota regressiva de IR de 22,5% a 15,0% incidida sobre o lucro obtido no momento do resgate. | Q22: 1000 | R22: ABERTO | S22: - | T22: 1000 | U22: 1000 | V22: Fechamento | W22: D+1 (útil) | X22: D+30 (corridos) | Y22: D+1 (útil) | Z22: 31 | AA22: - | AB22: - | AC22: ADAM MACRO ADVISORY RESP LIMITADA FIF CIC MULTIMERCADO | AD22: 0.019 | AE22: 0.119 | AF22: 0.025 | AG22: 0.2 | AH22: Janeiro / Julho | AI22: Junho | AJ22: CDI | AK22: 42488 | AL22: https://www.xpi.com.br/investimentos/fundos-de-investimento/lista/#/detalhes/aa7ededd-37d2-42bd-9e92-d2810af954ea | AM22: 0.14386716 | AN22: 0.032715581 | AO22: 0.10532404 | AP22: 0.14205274 | AQ22: 0.13006515 | AR22: 0.29482157 | AS22: 0.066798775 | AT22: -0.033692782 | AU22: - | AV22: - | AW22: 0.085626816 | AX22: 13.187472 | AY22: 0.72057018 | AZ22: 0.71032948 | BA22: 1.0857575 | BB22: 1.0095285 | BC22: 2.711259 | BD22: 0.51196846 | BE22: - | BF22: - | BG22: - | BH22: 0.87569739 | BI22: 0.13295778 | BJ22: -0.012686771 | BK22: -0.04295087 | BL22: 0.0099218022 | BM22: 0.0010875193 | BN22: 0.18608184 | BO22: -0.063675619 | BP22: -0.15742282 | BQ22: - | BR22: - | BS22: -0.011071849 | BT22: 0.10631566 | BU22: 0.074179709 | BV22: -0.30592311 | BW22: -0.066213039 | BX22: -0.1257028 | BY22: -0.1257028 | BZ22: 0.089599485 | CA22: -0.25937068 | CB22: 0.18834079 | CC22: -0.19605669 | CD22: -0.19544844 | CE22: 0.38710536 | CF22: -0.091457238 | CG22: 2.2666775 | CH22: 0.2342 | CI22: 0.15 | CJ22: 0.0044498 | CK22: - | CL22: 0.0044498 | CM22: 95178917 | CN22: 99207443 | CO22: -18670455 | CP22: - | CQ22: - | CR22: - | CS22: - | CT22: - | CU22: - | CV22: BRADM8CTF008 | CW22: - | CX22: 25569.626
B23: 52297687000172 | C23: Adam Renda Fixa Ativa Advisory FIC FIF RF LP RL | D23: 11 | G23: Adam Capital | H23: BNY Mellon Serviços Financeiros | I23: BNY Mellon Banco | J23: KPMG | K23: Geral | L23: Investidores em geral | M23: Renda Fixa | N23: Renda Fixa Duração Livre Crédito Livre | O23: Renda Fixa Ativo | P23: Longo Prazo | Q23: 500 | R23: ABERTO | S23: - | T23: 100 | U23: 500 | V23: Fechamento | W23: D+0 | X23: D+5 (útil) | Y23: D+1 (útil) | Z23: 6 | AA23: - | AB23: - | AC23: ADAM RENDA FIXA ATIVA ADVISORY RESP LIMITADA FIF CIC RENDA FIXA LP | AD23: 0.009 | AE23: 0.109 | AF23: 0.01 | AG23: 0.2 | AH23: Janeiro / Julho | AI23: Junho | AJ23: CDI | AK23: 45198 | AL23: https://www.xpi.com.br/investimentos/fundos-de-investimento/lista/#/detalhes/0692f533-5c3f-48b7-9afd-d3c177f8feab | AM23: 0.010608764 | AN23: 0.046987562 | AO23: 0.14079427 | AP23: 0.13060697 | AQ23: - | AR23: 0.1114118 | AS23: - | AT23: - | AU23: - | AV23: - | AW23: 0.12786373 | AX23: 0.97244415 | AY23: 1.0349147 | AZ23: 0.94954889 | BA23: 0.99293951 | BB23: - | BC23: 1.0245731 | BD23: - | BE23: - | BF23: - | BG23: - | BH23: 0.99829721 | BI23: -0.00030061729 | BJ23: 0.0015852096 | BK23: -0.0074806341 | BL23: -0.00082074853 | BM23: - | BN23: 0.0026720749 | BO23: - | BP23: - | BQ23: - | BR23: - | BS23: -0.00019333406 | BT23: 0.0032463489 | BU23: 0.0047717435 | BV23: -2.0127983 | BW23: -0.034740524 | BX23: -0.00028012777 | BY23: -0.00091972406 | BZ23: 0.002894796 | CA23: 0.15810586 | CB23: -0.077647673 | CC23: 0.19687328 | CD23: 0.33420343 | CE23: -0.11736892 | CF23: 0.14650892 | CG23: 1.3619678 | CH23: 0.3 | CI23: 0.25 | CJ23: 0.0027 | CK23: - | CL23: 0.0027 | CM23: 13488117 | CN23: 15035638 | CO23: -4477145.2 | CP23: - | CQ23: - | CR23: - | CS23: - | CT23: - | CU23: - | CV23: BR0H18CTF004 | CW23: - | CX23: 25569.626
B24: 35828705000186 | C24: AF Global Bonds CI RF CP RL | D24: 16 | G24: AF Invest Investimentos | H24: Santander Caceis | I24: Santander Caceis | J24: PriceWaterhouseCoopers | K24: Intranet | L24: Investidores qualificados | M24: Renda Fixa | N24: Renda Fixa Investimento no Exterior | O24: Internacional Renda Fixa Hedgeado | P24: Longo Prazo: Haverá cobrança de IR no último dia útil dos meses de maio e novembro de cada ano sob a alíquota de 15% (“come-cotas”), ou no resgate, se ocorrido em data anterior, seguindo tabela regressiva partindo de 22,5% para intervalo entre aplicação e resgate menor do que 6 meses à 15% se o intervalo entre aplicação e resgate for maior do que 2 anos. | Q24: 1000 | R24: ABERTO | S24: - | T24: 1000 | U24: 500 | V24: Fechamento | W24: D+0 | X24: D+15 (corridos) | Y24: D+1 (útil) | Z24: 16 | AA24: - | AB24: - | AC24: - | AD24: 0.005 | AE24: - | AF24: 0.0075 | AG24: 0.2 | AH24: - | AI24: - | AJ24: CDI | AK24: 44048 | AL24: https://www.xpi.com.br/investimentos/fundos-de-investimento/lista/#/detalhes/f1912c9d-b780-43c2-97e7-bb62f95d86a7 | AM24: 0.01530381 | AN24: 0.042283182 | AO24: 0.14075502 | AP24: 0.13137745 | AQ24: 0.13565437 | AR24: 0.09920286 | AS24: 0.10807567 | AT24: 0.12451628 | AU24: - | AV24: - | AW24: 0.10190691 | AX24: 1.4028119 | AY24: 0.93129936 | AZ24: 0.94928413 | BA24: 0.99915828 | BB24: 1.0585512 | BC24: 0.91229638 | BD24: 0.82832861 | BE24: 1.0063545 | BF24: - | BG24: - | BH24: 0.96084448 | BI24: 0.004394429 | BJ24: -0.0031191706 | BK24: -0.0075198913 | BL24: -9.7814483e-05 | BM24: 0.0066510508 | BN24: -0.0095368679 | BO24: -0.02239872 | BP24: 0.00078623988 | BQ24: - | BR24: - | BS24: -0.0037546112 | BT24: 0.014172437 | BU24: 0.0250757 | BV24: -0.45679751 | BW24: -0.10768012 | BX24: -0.0037300944 | BY24: -0.038111782 | BZ24: 0.018327322 | CA24: 0.20632588 | CB24: -0.056843061 | CC24: 0.25808484 | CD24: 0.19836152 | CE24: 0.16878386 | CF24: 0.24345097 | CG24: 1.7404469 | CH24: 0.27 | CI24: 0.15 | CJ24: 0.00135 | CK24: - | CL24: 0.00135 | CM24: 28760078 | CN24: 30126787 | CO24: -3904629.6 | CP24: - | CQ24: - | CR24: - | CS24: - | CT24: - | CU24: - | CV24: BR04RXCTF008 | CW24: - | CX24: 25569.626
B25: 44025131000107 | C25: AF Horizonte FIF Multimercado CP RL | D25: 13 | G25: AF Invest Investimentos | H25: BTG Pactual Serviços Financeiros | I25: Banco BTG Pactual | J25: EY | K25: Geral | L25: Investidores qualificados | M25: Multimercado | N25: Multimercados Livre | O25: Crédito High Yield | P25: Longo Prazo | Q25: 1000 | R25: ABERTO | S25: - | T25: 1000 | U25: 1000 | V25: Fechamento | W25: D+0 | X25: D+59 (corridos) | Y25: D+1 (útil) | Z25: 60 | AA25: - | AB25: - | AC25: - | AD25: 0.01 | AE25: - | AF25: 0.01 | AG25: 0.2 | AH25: Dezembro / Junho | AI25: Novembro / Maio | AJ25: CDI | AK25: 44523 | AL25: https://www.xpi.com.br/investimentos/fundos-de-investimento/lista/#/detalhes/cb30cbb8-f0b6-4d23-ab4c-c4cdd49bc53f | AM25: 0.01076937 | AN25: 0.022877542 | AO25: 0.1238972 | AP25: 0.12571127 | AQ25: 0.13484002 | AR25: 0.1299722 | AS25: 0.11274598 | AT25: 0.14933649 | AU25: - | AV25: - | AW25: 0.13031539 | AX25: 0.98716598 | AY25: 0.50388451 | AZ25: 0.83559118 | BA25: 0.95352387 | BB25: 1.0513784 | BC25: 1.1952595 | BD25: 0.86412342 | BE25: 1.2069542 | BF25: - | BG25: - | BH25: 1.0287516 | BI25: -0.00014001117 | BJ25: -0.02252481 | BK25: -0.024377703 | BL25: -0.0054136244 | BM25: 0.005840295 | BN25: 0.021232469 | BO25: -0.017728415 | BP25: 0.025606456 | BQ25: - | BR25: - | BS25: 0.0032325752 | BT25: 0.011460381 | BU25: 0.0091456705 | BV25: -1.8676256 | BW25: 0.29540747 | BX25: -0.012972187 | BY25: -0.012972187 | BZ25: 0.0035993587 | CA25: 0.035268382 | CB25: -0.01230496 | CC25: 0.065103862 | CD25: 0.04731936 | CE25: -0.0021827264 | CF25: 0.11107787 | CG25: 1.7186055 | CH25: 0.24 | CI25: 0.09 | CJ25: 0.0024 | CK25: - | CL25: 0.0024 | CM25: 2.2967051e+08 | CN25: 2.263173e+08 | CO25: -2959420.5 | CP25: - | CQ25: - | CR25: - | CS25: - | CT25: - | CU25: - | CV25: BR0ACVCTF007 | CW25: - | CX25: 25569.626
B26: 29044189000104 | C26: AF Invest Geraes 30 FIRF CP | D26: 10 | G26: AF Invest Investimentos | H26: BTG Pactual Serviços Financeiros | I26: Banco BTG Pactual | J26: KPMG | K26: Geral | L26: Investidores em geral | M26: Renda Fixa | N26: Renda Fixa Duração Livre Grau de Investimento | O26: Crédito High Grade | P26: Longo Prazo: Haverá cobrança de IR no último dia útil dos meses de maio e novembro de cada ano sob a alíquota de 15% (“come-cotas”), ou no resgate, se ocorrido em data anterior, seguindo tabela regressiva partindo de 22,5% para intervalo entre aplicação e resgate menor do que 6 meses à 15% se o intervalo entre aplicação e resgate for maior do que 2 anos._x000D_ | Q26: 500 | R26: ABERTO | S26: - | T26: 100 | U26: 500 | V26: Fechamento | W26: D+0 | X26: D+30 (corridos) | Y26: D+1 (útil) | Z26: 31 | AA26: - | AB26: - | AC26: - | AD26: 0.005 | AE26: - | AF26: 0.008 | AG26: - | AH26: - | AI26: - | AJ26: CDI | AK26: 43187 | AL26: https://www.xpi.com.br/investimentos/fundos-de-investimento/lista/#/detalhes/f95a255b-c0bc-43da-b128-73a7acdbf874 | AM26: 0.0094101092 | AN26: 0.035013289 | AO26: 0.13848081 | AP26: 0.13545335 | AQ26: 0.14113547 | AR26: 0.12729654 | AS26: 0.10357166 | AT26: 0.14697884 | AU26: - | AV26: - | AW26: 0.093679999 | AX26: 0.86257037 | AY26: 0.77117786 | AZ26: 0.93394634 | BA26: 1.0321265 | BB26: 1.1070965 | BC26: 1.1706535 | BD26: 0.79380835 | BE26: 1.1878994 | BF26: - | BG26: - | BH26: 1.0525934 | BI26: -0.0014992723 | BJ26: -0.010389063 | BK26: -0.0097941007 | BL26: 0.0037270636 | BM26: 0.012109215 | BN26: 0.018556813 | BO26: -0.02690273 | BP26: 0.023248802 | BQ26: - | BR26: - | BS26: 0.0042982291 | BT26: 0.0090937745 | BU26: 0.011010765 | BV26: -0.93793482 | BW26: 0.29855922 | BX26: -0.0030525598 | BY26: -0.055045721 | BZ26: 0.001765241 | CA26: 0.15295036 | CB26: -0.081307988 | CC26: 0.13838521 | CD26: 0.15431731 | CE26: -0.031235102 | CF26: 0.13693388 | CG26: 2.0579606 | CH26: 0.27 | CI26: - | CJ26: 0.00135 | CK26: - | CL26: 0.00135 | CM26: 3.146219e+08 | CN26: 3.5232717e+08 | CO26: -32996323 | CP26: - | CQ26: - | CR26: - | CS26: - | CT26: - | CU26: - | CV26: BR002TCTF003 | CW26: - | CX26: 25569.626
B27: 9720734000110 | C27: AF Invest Geraes FIF RF CP RL | D27: 10 | F27: ««« | G27: AF Invest Investimentos | H27: BTG Pactual Serviços Financeiros | I27: Banco BTG Pactual | J27: EY | K27: Geral | L27: Investidores em geral | M27: Renda Fixa | N27: Renda Fixa Duração Livre Grau de Investimento | O27: Crédito Liquidez | P27: Longo Prazo - Alíquota regressiva de IR de 22,5% a 15,0% incidida sobre o lucro obtido no momento do resgate. | Q27: 500 | R27: ABERTO | S27: - | T27: 100 | U27: 500 | V27: Fechamento | W27: D+0 | X27: D+0 | Y27: D+1 (útil) | Z27: 1 | AA27: - | AB27: - | AC27: - | AD27: 0.004 | AE27: - | AF27: 0.006 | AG27: - | AH27: - | AI27: - | AJ27: CDI | AK27: 39702 | AL27: https://www.xpi.com.br/investimentos/fundos-de-investimento/lista/#/detalhes/cc7bce2d-35e5-431b-8b42-a0542280a0d7 | AM27: 0.010127895 | AN27: 0.039935965 | AO27: 0.14436146 | AP27: 0.13360338 | AQ27: 0.13655073 | AR27: 0.11973905 | AS27: 0.11577234 | AT27: 0.13770026 | AU27: - | AV27: - | AW27: 0.10164526 | AX27: 0.92836565 | AY27: 0.87960123 | AZ27: 0.97360681 | BA27: 1.0171482 | BB27: 1.0664582 | BC27: 1.1011527 | BD27: 0.88731847 | BE27: 1.1129089 | BF27: - | BG27: - | BH27: 1.0536536 | BI27: -0.00078148647 | BJ27: -0.0054663872 | BK27: -0.0039134485 | BL27: 0.0019909218 | BM27: 0.007543513 | BN27: 0.010999322 | BO27: -0.014702054 | BP27: 0.013970222 | BQ27: - | BR27: - | BS27: 0.0047205362 | BT27: 0.0046669238 | BU27: 0.0063204626 | BV27: -0.72958949 | BW27: 0.38583465 | BX27: -0.0020367311 | BY27: -0.036711977 | BZ27: 0.00046507659 | CA27: 0.077875057 | CB27: -0.035615895 | CC27: 0.08903046 | CD27: 0.1135462 | CE27: -0.03217238 | CF27: 0.07603618 | CG27: 5.4794122 | CH27: 0.25 | CI27: - | CJ27: 0.001 | CK27: - | CL27: 0.001 | CM27: 5.4246401e+08 | CN27: 5.9206749e+08 | CO27: -31455777 | CP27: - | CQ27: - | CR27: - | CS27: - | CT27: - | CU27: - | CV27: BRAFI3CTF003 | CW27: - | CX27: 25569.626
B28: 12987743000186 | C28: Alaska Black FIC de FIA - BDR NÍVEL I | D28: 38 | F28: « | G28: Alaska Asset Management | H28: BTG Pactual Serviços Financeiros | I28: Banco BTG Pactual | J28: EY | K28: Geral | L28: Investidores qualificados | M28: Ações | N28: Ações Livre | O28: Renda Variável Long Only | P28: Renda Variável - Alíquota de IR de 15% incidida sobre o lucro obtido no momento do resgate. | Q28: 5000 | R28: ABERTO | S28: - | T28: 1000 | U28: 5000 | V28: Fechamento | W28: D+1 (útil) | X28: D+30 (corridos) | Y28: D+2 (útil) | Z28: 32 | AA28: - | AB28: - | AC28: ALASKA BLACK FIF CIC AÇÕES | AD28: 0.0185 | AE28: 0.1685 | AF28: 0.0185 | AG28: 0.2 | AH28: Janeiro / Julho | AI28: Junho | AJ28: - | AK28: 40567 | AL28: https://www.xpi.com.br/investimentos/fundos-de-investimento/lista/#/detalhes/04570145-f065-4cba-a5a8-2ab26447c7c9 | AM28: -0.014544967 | AN28: 0.11954405 | AO28: 0.24590465 | AP28: 0.002182937 | AQ28: 0.092144338 | AR28: -0.57148685 | AS28: 0.5874196 | AT28: 0.090991395 | AU28: - | AV28: - | AW28: 0.074804301 | AX28: - | AY28: 2.6329924 | AZ28: 1.6584374 | BA28: 0.015595455 | BB28: 0.68954897 | BC28: - | BD28: 4.502183 | BE28: 0.73540264 | BF28: - | BG28: - | BH28: 0.6316525 | BI28: -0.025454348 | BJ28: 0.074141694 | BK28: 0.097629746 | BL28: -0.12087106 | BM28: -0.036595305 | BN28: -0.68022657 | BO28: 0.45694521 | BP28: -0.032738641 | BQ28: - | BR28: - | BS28: -0.039003061 | BT28: 0.43958006 | BU28: 0.38402963 | BV28: 0.40518659 | BW28: 0.14308078 | BX28: -0.26783711 | BY28: -0.73364298 | BZ28: 1.2558545 | CA28: 0.89421482 | CB28: -0.5181263 | CC28: 0.66051116 | CD28: 0.54954833 | CE28: 0.075890243 | CF28: 0.76381254 | CG28: 2.9959189 | CH28: 0.25 | CI28: 0.15 | CJ28: 0.004625 | CK28: - | CL28: 0.004625 | CM28: 8.223804e+08 | CN28: 8.4661599e+08 | CO28: -56397021 | CP28: - | CQ28: - | CR28: - | CS28: - | CT28: - | CU28: - | CV28: BRSKP7CTF008 | CW28: - | CX28: 25569.626
B29: 26673556000132 | C29: Alaska Institucional Long Only FIF em Ações RL | D29: 28 | F29: «««« | G29: Alaska Asset Management | H29: BTG Pactual Serviços Financeiros | I29: Banco BTG Pactual | J29: KPMG | K29: Geral | L29: Investidores em geral | M29: Ações | N29: Ações Livre | O29: Renda Variável Long Only | P29: Renda Variável - Alíquota de IR de 15% incidida sobre o lucro obtido no momento do resgate. | Q29: 1000 | R29: ABERTO | S29: - | T29: 500 | U29: 1000 | V29: Fechamento | W29: D+1 (útil) | X29: D+30 (corridos) | Y29: D+2 (útil) | Z29: 32 | AA29: Sim | AB29: 0.05 | AC29: - | AD29: 0.02 | AE29: - | AF29: 0.025 | AG29: 0.2 | AH29: Janeiro / Julho | AI29: Junho | AJ29: Ibovespa | AK29: 42787 | AL29: https://www.xpi.com.br/investimentos/fundos-de-investimento/lista/#/detalhes/ddd2f6a6-42a9-4fe2-935f-0ccf566b3d29 | AM29: -0.039936879 | AN29: 0.019593066 | AO29: 0.047964323 | AP29: 0.017796527 | AQ29: 0.084586559 | AR29: -0.32888698 | AS29: 0.35564604 | AT29: 0.043139551 | AU29: - | AV29: - | AW29: 0.14276479 | AX29: - | AY29: 0.43154296 | AZ29: 0.3234824 | BA29: 0.12813439 | BB29: 0.62836497 | BC29: - | BD29: 2.7257919 | BE29: 0.34865868 | BF29: - | BG29: - | BH29: 1.9895676 | BI29: -0.050846261 | BJ29: -0.025809287 | BK29: -0.10031058 | BL29: -0.10632551 | BM29: -0.044091817 | BN29: -0.43762671 | BO29: 0.22517165 | BP29: -0.080590485 | BQ29: - | BR29: - | BS29: 0.066253935 | BT29: 0.28724769 | BU29: 0.26976876 | BV29: -0.17514008 | BW29: 0.31192876 | BX29: -0.18437815 | BY29: -0.51933507 | BZ29: 1.0418354 | CA29: 0.84595023 | CB29: -0.41605374 | CC29: 0.61424126 | CD29: 0.49925452 | CE29: 0.11942061 | CF29: 0.69649703 | CG29: 3.3857995 | CH29: 0.2 | CI29: 0.15 | CJ29: 0.004 | CK29: - | CL29: 0.004 | CM29: 8.4165369e+08 | CN29: 8.9994182e+08 | CO29: -61967975 | CP29: - | CQ29: - | CR29: - | CS29: - | CT29: - | CU29: - | CV29: BRASK4CTF002 | CW29: - | CX29: 25569.626
B30: 34839385000105 | C30: AlphaKey Ações FIF em Cotas de FIA RL | D30: 38 | F30: «« | G30: ALPHAKEY CAPITAL MANAGEMENT INVESTIMENTOS LTDA | H30: BTG Pactual Serviços Financeiros | I30: Banco BTG Pactual | J30: EY | K30: Geral | L30: Investidores qualificados | M30: Ações | N30: Ações Livre | O30: Renda Variável Long Biased | P30: Renda Variável - Alíquota de IR de 15% incidida sobre o lucro obtido no momento do resgate._x000D_ | Q30: 5000 | R30: ABERTO | S30: - | T30: 1000 | U30: 1000 | V30: Fechamento | W30: D+1 (útil) | X30: D+30 (corridos) | Y30: D+2 (útil) | Z30: 32 | AA30: - | AB30: - | AC30: ALPHAKEY FIF CIC AÇÕES | AD30: 0.0187 | AE30: 0.1487 | AF30: 0.022 | AG30: 0.2 | AH30: - | AI30: - | AJ30: - | AK30: 43889 | AL30: https://www.xpi.com.br/investimentos/fundos-de-investimento/lista/#/detalhes/df57c52c-b420-4be2-bad2-06fa72983845 | AM30: -0.0086837593 | AN30: 0.075046687 | AO30: 0.31314754 | AP30: 0.28425405 | AQ30: 0.33411072 | AR30: -0.0030219311 | AS30: 0.32708484 | AT30: -0.10433458 | AU30: - | AV30: - | AW30: 0.1230343 | AX30: - | AY30: 1.6529251 | AZ30: 2.1119389 | BA30: 2.3168833 | BB30: 3.1312799 | BC30: - | BD30: 2.5068891 | BE30: - | BF30: - | BG30: - | BH30: 1.4744245 | BI30: -0.019593141 | BJ30: 0.029644335 | BK30: 0.16487263 | BL30: 0.1439099 | BM30: 0.20548433 | BN30: -0.11176166 | BO30: 0.19661044 | BP30: -0.22806461 | BQ30: - | BR30: - | BS30: 0.036539591 | BT30: 0.15609255 | BU30: 0.27921144 | BV30: 0.93807236 | BW30: 0.24113003 | BX30: -0.068126624 | BY30: -0.52376957 | BZ30: 1.0338787 | CA30: 0.87369705 | CB30: -0.41323054 | CC30: 0.62785436 | CD30: 0.52900174 | CE30: 0.14036081 | CF30: 0.72629673 | CG30: 2.3699987 | CH30: 0.25 | CI30: 0.15 | CJ30: 0.004675 | CK30: - | CL30: 0.004675 | CM30: 2.1111967e+08 | CN30: 1.8448144e+08 | CO30: 37323421 | CP30: - | CQ30: - | CR30: - | CS30: - | CT30: - | CU30: - | CV30: BR050ECTF004 | CW30: - | CX30: 25569.626
B31: 36352721000108 | C31: AlphaKey Institucional FIF em Cotas de FIA RL | D31: 43 | G31: ALPHAKEY CAPITAL MANAGEMENT INVESTIMENTOS LTDA | H31: BTG Pactual Serviços Financeiros | I31: Banco BTG Pactual | J31: KPMG | K31: Geral | L31: Investidores em geral | M31: Ações | N31: Ações Livre | O31: Renda Variável Long Only | P31: Renda Variável - Alíquota de IR de 15% incidida sobre o lucro obtido no momento do resgate._x000D_ | Q31: 1000 | R31: ABERTO | S31: - | T31: 1000 | U31: 1000 | V31: Fechamento | W31: D+1 (útil) | X31: D+30 (corridos) | Y31: D+2 (útil) | Z31: 32 | AA31: - | AB31: - | AC31: ALPHAKEY INSTITUCIONAL FIF CIC AÇÕES | AD31: 0.0189 | AE31: 0.1289 | AF31: 0.0235 | AG31: 0.2 | AH31: Janeiro / Julho | AI31: Junho | AJ31: Ibovespa | AK31: 44000 | AL31: https://www.xpi.com.br/investimentos/fundos-de-investimento/lista/#/detalhes/c5e92b06-8749-4f35-bf57-218dbaf3f62f | AM31: -0.017841527 | AN31: 0.075637136 | AO31: 0.28464072 | AP31: 0.23402702 | AQ31: 0.24878371 | AR31: -0.075605608 | AS31: 0.25779357 | AT31: -0.17936287 | AU31: - | AV31: - | AW31: 0.051998334 | AX31: - | AY31: 1.6659299 | AZ31: 1.9196823 | BA31: 1.8655526 | BB31: 2.1583305 | BC31: - | BD31: 1.9758173 | BE31: - | BF31: - | BG31: - | BH31: 0.44459784 | BI31: -0.028750908 | BJ31: 0.030234784 | BK31: 0.13636581 | BL31: 0.096477741 | BM31: 0.11971753 | BN31: -0.18434534 | BO31: 0.12731917 | BP31: -0.30309291 | BQ31: - | BR31: - | BS31: -0.058155879 | BT31: 0.17318692 | BU31: 0.22095882 | BV31: 0.7347665 | BW31: -0.10465481 | BX31: -0.08728993 | BY31: -0.48131424 | BZ31: 1.0187571 | CA31: 0.91387854 | CB31: -0.44420309 | CC31: 0.67119794 | CD31: 0.557161 | CE31: 0.14848068 | CF31: 0.76729233 | CG31: 1.344879 | CH31: 0.25 | CI31: 0.15 | CJ31: 0.004725 | CK31: - | CL31: 0.004725 | CM31: 15594410 | CN31: 13206818 | CO31: 3308265.8 | CP31: - | CQ31: - | CR31: - | CS31: - | CT31: - | CU31: - | CV31: BR04DSCTF008 | CW31: - | CX31: 25569.626
B32: 52304477000164 | C32: AlphaKey LS FIF em Cotas FIM RL | D32: 13 | G32: ALPHAKEY CAPITAL MANAGEMENT INVESTIMENTOS LTDA | H32: BTG Pactual Serviços Financeiros | I32: Banco BTG Pactual | J32: KPMG | K32: Geral | L32: Investidores em geral | M32: Multimercado | N32: Multimercados Livre | O32: Multiestratégia | P32: Longo Prazo | Q32: 1000 | R32: ABERTO | S32: - | T32: 1000 | U32: 1000 | V32: Fechamento | W32: D+1 (útil) | X32: D+30 (corridos) | Y32: D+2 (útil) | Z32: 32 | AA32: - | AB32: - | AC32: ALPHAKEY LONG SHORT FIF CIC MULTIMERCADO | AD32: 0.0187 | AE32: 0.1487 | AF32: 0.0237 | AG32: 0.2 | AH32: Junho / Dezembro | AI32: Maio / Novembro | AJ32: CDI | AK32: 45197 | AL32: https://www.xpi.com.br/investimentos/fundos-de-investimento/lista/#/detalhes/6806aa48-c47d-4e5d-bcc5-95d2e3a3e9e7 | AM32: 0.0079921915 | AN32: 0.049017246 | AO32: 0.18433761 | AP32: 0.16204963 | AQ32: - | AR32: 0.12643342 | AS32: - | AT32: - | AU32: - | AV32: - | AW32: 0.16324673 | AX32: 0.73259804 | AY32: 1.0796191 | AZ32: 1.2432151 | BA32: 1.2501634 | BB32: - | BC32: 1.162716 | BD32: - | BE32: - | BF32: - | BG32: - | BH32: 1.3084469 | BI32: -0.00291719 | BJ32: 0.0036148943 | BK32: 0.036062699 | BL32: 0.028705932 | BM32: - | BN32: 0.017693688 | BO32: - | BP32: - | BQ32: - | BR32: - | BS32: 0.034214287 | BT32: 0.024528755 | BU32: 0.024488416 | BV32: 1.2736607 | BW32: 1.2671514 | BX32: -0.0063694808 | BY32: -0.0091660998 | BZ32: 0.050039444 | CA32: 0.38623952 | CB32: -0.14762106 | CC32: 0.33830555 | CD32: 0.30111337 | CE32: 0.20245718 | CF32: 0.42391748 | CG32: 1.4752664 | CH32: 0.24 | CI32: 0.15 | CJ32: 0.004488 | CK32: 0.00094217941 | CL32: 0.0054301794 | CM32: 1.6468241e+08 | CN32: 1.2638527e+08 | CO32: 49535285 | CP32: - | CQ32: - | CR32: - | CS32: - | CT32: - | CU32: - | CV32: BR0H0MCTF007 | CW32: - | CX32: 25569.626
B33: 64154430000140 | C33: AP LB II FIF em Cotas de FIA | D33: 26 | G33: Absoluto Partners Investimentos | H33: BTG Pactual Serviços Financeiros | I33: Banco BTG Pactual | J33: EY | K33: Intranet | L33: Não definido | M33: Ações | N33: - | O33: Renda Variável Long Biased | P33: Ações | Q33: 200000 | R33: ABERTO | S33: - | T33: 50000 | U33: 50000 | V33: Fechamento | W33: D+1 (útil) | X33: D+60 (corridos) | Y33: D+2 (útil) | Z33: 62 | AA33: - | AB33: - | AC33: - | AD33: 0.0185 | AE33: - | AF33: 0.0189 | AG33: 0.2 | AH33: Janeiro / Julho | AI33: Junho | AJ33: CDI | AK33: 46126 | AL33: https://www.xpi.com.br/investimentos/fundos-de-investimento/lista/#/detalhes/3518c3f7-7b7c-4a9a-9ad4-87317a405c1c | AM33: - | AN33: - | AO33: - | AP33: - | AQ33: - | AR33: - | AS33: - | AT33: - | AU33: - | AV33: - | AW33: - | AX33: - | AY33: - | AZ33: - | BA33: - | BB33: - | BC33: - | BD33: - | BE33: - | BF33: - | BG33: - | BH33: - | BI33: - | BJ33: - | BK33: - | BL33: - | BM33: - | BN33: - | BO33: - | BP33: - | BQ33: - | BR33: - | BS33: - | BT33: - | BU33: 0.15567095 | BV33: - | BW33: -7.2603242 | BX33: - | BY33: -0.050906282 | BZ33: 0.8723754 | CA33: - | CB33: - | CC33: - | CD33: - | CE33: - | CF33: - | CG33: 0.96077857 | CH33: 0.03 | CI33: - | CJ33: 0.000555 | CK33: - | CL33: 0.000555 | CM33: 2882335.7 | CN33: - | CO33: - | CP33: - | CQ33: - | CR33: - | CS33: - | CT33: - | CU33: - | CV33: BR0R3FCTF003 | CW33: - | CX33: 25569.626
